<?xml version="1.0" ?>
<robot name="pioneer2dx" xmlns:xacro="http://ros.org/wiki/xacro">
	<material name="chasis_gazebo">
		<color rgba="1 0 0 1"/>
	</material>
	<material name="ruedas_gazebo">
		<color rgba="0 0 0 1"/>
	</material>
	<link name="base_link"/>
	<joint name="base_link_to_chassis" type="fixed">
		<parent link="base_link"/>
		<child link="chassis"/>
	</joint>
	<link name="chassis">
		<origin xyz="0 0 0.16" rpy="0 0 0"/>
		<inertial>
			<mass value="5.67"/>
			<inertia ixx="0.07" iyy="0.08" izz="0.10" ixz="0" ixy="0" iyz="0" />
		</inertial>
		<collision name="collision">
			<geometry>
				<box size="0.445 0.277 0.17"/>
			</geometry>
		</collision>
		<collision name="castor_collision">
			<origin xyz="-0.2 0 -0.12" rpy="0 0 0"/>
			<geometry>
				<sphere radius="0.04"/>
			</geometry>
			<surface>
				<friction>
					<ode>
						<mu>0</mu>
						<mu2>0</mu2>
						<slip1>1.0</slip1>
						<slip2>1.0</slip2>
					</ode>
				</friction>
			</surface>
		</collision>
		<visual name="visual">
			<origin xyz="0 0 0.04" rpy="0 0 0"/>
			<geometry>
				<!--<mesh filename="package://pioneer2dx/meshes/chassis.dae"/>-->
				<mesh filename="file://$(arg meshlocation)/meshes/chassis.dae"/>
			</geometry>
		</visual>
		<visual name="castor_visual">
			<origin xyz="-0.20 0 -0.12" rpy="0 0 0"/>
			<geometry>
				<sphere radius="0.04"/>
			</geometry>
			<material name="chasis_gazebo"/>
			<!--<material>
				<script>
					<uri>file://media/materials/scripts/gazebo.material</uri>
					<name>Gazebo/FlatBlack</name>
				</script>
			</material>-->
		</visual>
	</link>
	<xacro:macro name="wheel" params="name pos">
		<xacro:property name="position" value="0.1 ${pos*0.17} -0.037" />
		<xacro:property name="position2" value="0 0 0" />
		<xacro:property name="orientation" value="0 1.5707 1.570" />
		<link name="${name}_wheel">
			<inertial>
				<mass value="1.5"/>
				<inertia ixx="0.0051" iyy="0.0051" izz="0.090" ixz="0" ixy="0" iyz="0" />
			</inertial>
			<collision name="collision">
				<origin xyz="${position2}" rpy="${orientation}"/>
				<geometry>
					<cylinder radius="0.11" length="0.05"/>
				</geometry>
				<!--<contact_coefficients mu="100000" kp="0" kd="0"/>-->
				<gazebo>
				<surface>
					<friction>
						<ode>
							<mu>100000.0</mu>
							<mu2>100000.0</mu2>
							<slip1>0.0</slip1>
							<slip2>0.0</slip2>
						</ode>
					</friction>
				</surface>
			</gazebo>
			</collision>
			<visual name="${name}_visual">
				<origin xyz="${position2}" rpy="${orientation}"/>
				<geometry>
					<cylinder radius="0.11" length="0.05"/>
				</geometry>

				<material name="ruedas_gazebo"/>
				<!--
		<material>
			<script>
				<uri>file://media/materials/scripts/gazebo.material</uri>
				<name>Gazebo/FlatBlack</name>
			</script>
		</material>
	-->
      </visual>
    </link>    
    <joint type="revolute" name="${name}_wheel_hinge">
	    <origin xyz="${position}" rpy="0 0 0"/>
	    <child link="${name}_wheel"/>
	    <parent link="chassis"/>
	    <axis xyz="0 1 0"/>
	    <limit effort="30" velocity="1" lower="-7" upper="7" />
    </joint>
    </xacro:macro>
    <xacro:wheel name="right" pos="1" />
    <xacro:wheel name="left" pos="-1" />
    <link name="Camera">
	    <visual name="camera_visual">
		    <origin xyz="0 0 0" rpy="0 0 0"/>
		    <geometry>
			    <box size="0.1 0.1 0.1"/>
		    </geometry>
		    <material name="camera_color">
			    <color rgba="1 1 1 1"/>
		    </material>
		    
	    </visual>
    </link>
    <joint name="camera_to_chassis" type="fixed">
	    <parent link="chassis"/>
	    <child link="Camera"/>
	    <origin xyz="0.14 0 0.16" rpy="0 0 0" />
    </joint>

    <!-- Fuente: http://gazebosim.org/tutorials?tut=ros_gzplugins -->

    <!-- camera -->
  <gazebo reference="Camera">
    <sensor type="camera" name="camera1">
      <update_rate>30.0</update_rate>
      <camera name="head">
        <horizontal_fov>1.3962634</horizontal_fov>
        <image>
          <width>800</width>
          <height>800</height>
          <format>R8G8B8</format>
        </image>
        <clip>
          <near>0.02</near>
          <far>300</far>
        </clip>
        <noise>
          <type>gaussian</type>
          <!-- Noise is sampled independently per pixel on each frame.
               That pixel's noise value is added to each of its color
               channels, which at that point lie in the range [0,1]. -->
          <mean>0.0</mean>
          <stddev>0.007</stddev>
        </noise>
      </camera>
      <plugin name="camera_controller" filename="libgazebo_ros_camera.so">
        <alwaysOn>true</alwaysOn>
        <updateRate>0.0</updateRate>
        <cameraName>pioneer2dx/camera1</cameraName>
        <imageTopicName>image_raw</imageTopicName>
        <cameraInfoTopicName>camera_info</cameraInfoTopicName>
        <frameName>camera_link</frameName>
        <hackBaseline>0.07</hackBaseline>
        <distortionK1>0.0</distortionK1>
        <distortionK2>0.0</distortionK2>
        <distortionK3>0.0</distortionK3>
        <distortionT1>0.0</distortionT1>
        <distortionT2>0.0</distortionT2>
      </plugin>
    </sensor>
  </gazebo>
    <!--
	    <plugin filename="libDiffDrivePlugin.so" name="diff_drive">
	      <left_joint>left_wheel_hinge</left_joint>
	      <right_joint>right_wheel_hinge</right_joint>
	      <torque>5</torque>
	    </plugin>
    -->
  </robot>

