<?xml version="1.0" ?>
<robot name="pioneer2dx" xmlns:xacro="http://ros.org/wiki/xacro">
	<material name="chasis_gazebo">
		<color rgba="1 0 0 1"/>
	</material>
	<material name="ruedas_gazebo">
		<color rgba="0 0 0 1"/>
	</material>
	<link name="base_link"/>
	<joint name="base_link_to_chassis" type="fixed">
		<parent link="base_link"/>
		<child link="chassis"/>
	</joint>
	<link name="chassis">
		<origin xyz="0 0 0.16" rpy="0 0 0"/>
		<inertial>
			<mass value="5.67"/>
			<inertia ixx="0.07" iyy="0.08" izz="0.10" ixz="0" ixy="0" iyz="0" />
		</inertial>
		<collision name="collision">
			<geometry>
				<box size="0.445 0.277 0.17"/>
			</geometry>
		</collision>
		<collision name="castor_collision">
			<origin xyz="-0.2 0 -0.12" rpy="0 0 0"/>
			<geometry>
				<sphere radius="0.04"/>
			</geometry>
			<surface>
				<friction>
					<ode>
						<mu>0</mu>
						<mu2>0</mu2>
						<slip1>1.0</slip1>
						<slip2>1.0</slip2>
					</ode>
				</friction>
			</surface>
		</collision>
		<visual name="visual">
			<origin xyz="0 0 0.04" rpy="0 0 0"/>
			<geometry>
				<!--<mesh filename="package://pioneer2dx/meshes/chassis.dae"/>-->
				<mesh filename="file://$(arg meshlocation)/meshes/chassis.dae"/>
			</geometry>
		</visual>
		<visual name="castor_visual">
			<origin xyz="-0.20 0 -0.12" rpy="0 0 0"/>
			<geometry>
				<sphere radius="0.04"/>
			</geometry>
			<material name="chasis_gazebo"/>
			<!--<material>
				<script>
					<uri>file://media/materials/scripts/gazebo.material</uri>
					<name>Gazebo/FlatBlack</name>
				</script>
			</material>-->
		</visual>
	</link>
	<xacro:macro name="wheel" params="name pos">
		<link name="${name}_wheel">
			<origin xyz="0.1 ${pos} 0.11" rpy="0 1.5707 1.5707"/>
			<inertial>
				<mass value="1.5"/>
				<inertia ixx="0.0051" iyy="0.0051" izz="0.090" ixz="0" ixy="0" iyz="0" />
			</inertial>
			<collision name="collision">
				<geometry>
					<cylinder radius="0.11" length="0.05"/>
				</geometry>
				<surface>
					<friction>
						<ode>
							<mu>100000.0</mu>
							<mu2>100000.0</mu2>
							<slip1>0.0</slip1>
							<slip2>0.0</slip2>
						</ode>
					</friction>
				</surface>
			</collision>
			<visual name="${name}_visual">
				<geometry>
					<cylinder radius="0.11" length="0.05"/>
				</geometry>

				<material name="ruedas_gazebo"/>
				<!--
		<material>
			<script>
				<uri>file://media/materials/scripts/gazebo.material</uri>
				<name>Gazebo/FlatBlack</name>
			</script>
		</material>
	-->
      </visual>
    </link>    
    </xacro:macro>
    <xacro:wheel name="right" pos="0.17" />
    <xacro:wheel name="left" pos="-0.17" />

    <joint type="revolute" name="left_wheel_hinge">
	    <origin xyz="0 0 -0.03" rpy="0 0 0"/>
	    <child link="left_wheel"/>
	    <parent link="chassis"/>
	    <axis xyz="0 1 0"/>
	    <limit effort="30" velocity="1" lower="-7" upper="7" />
    </joint>
    <joint type="revolute" name="right_wheel_hinge">
	    <origin xyz="0 0 0.03" rpy="0 0 0"/>
	    <child link="right_wheel"/>
	    <parent link="chassis"/>
	    <axis xyz="0 1 0"/>

	    <limit effort="30" velocity="1.0" lower="-7" upper="7"/>
    </joint>
    <!--
	    <plugin filename="libDiffDrivePlugin.so" name="diff_drive">
	      <left_joint>left_wheel_hinge</left_joint>
	      <right_joint>right_wheel_hinge</right_joint>
	      <torque>5</torque>
	    </plugin>
    -->
  </robot>

